Workbook

Sheet Information
A1: URL | B1: https://www.ncbi.nlm.nih.gov/datasets/genome/GCF_000253315.1/
A2: NCBI RefSeq assembly | B2: GCF_000253315.1
A3: BioSample ID | B3: SAMEA2272047
A4: Sample name | B4: FR873482.1
A5: Assembly number | B5: ASM25331v1
A6: Chromosome ref seq | B6: NC_017595.1
B7: Ref Seq | C7: GenBank
A8: Genome Size | B8: 2.2 Mb | C8: 2.2 Mb
A9: Total ungapped length | B9: 2.2 Mb | C9: 2.2 Mb
A10: Number of chromosomes | B10: 1 | C10: 1
A11: Number of scaffolds | B11: 1 | C11: 1
A12: Scaffold N50 | B12: 2.2 Mb | C12: 2.2 Mb
A13: Scaffold N50 | B13: 1 | C13: 1
A14: Number of contigs | B14: 1 | C14: 1
A15: Contig N50 | B15: 2.2 Mb | C15: 2.2 Mb
A16: Contig L50 | B16: 1 | C16: 1
A17: GC percent | B17: 40 | C17: 40
A18: Assembly level | B18: Complete Genome | C18: Complete Genome
A19: Genes | B19: 2055 | C19: 2065
A20: Protein-coding | B20: 1936 | C20: 1979
A22: Chromosome | B22: FR873482.1 | C22: NC_017595.1
A25: CheckM analysis
A26: Completeness | B26: 0.9945
A27: Contamination | B27: 0.0066

Sheet Peptides
A1: Accession | B1: Begin | C1: End | D1: Chromosome | E1: Orientation | F1: Name | G1: Symbol | H1: Gene ID | I1: Gene Type | J1: Transcripts accession | K1: Transcript name | L1: Protein accession | M1: Protein name | N1: Protein length | O1: Locus tag
A2: FR873482.1 | B2: 104 | C2: 1468 | E2: plus | F2: chromosomal replication initiator protein dnaA | G2: dnaA | I2: protein-coding | L2: CCB94398.1 | M2: chromosomal replication initiator protein dnaA | N2: 454 | O2: SALIVA_0001
A3: FR873482.1 | B3: 1623 | C3: 2759 | E3: plus | F3: beta subunit of DNA polymerase III | G3: dnaN | I3: protein-coding | L3: CCB94399.1 | M3: beta subunit of DNA polymerase III | N3: 378 | O3: SALIVA_0002
A4: FR873482.1 | B4: 2811 | C4: 3002 | E4: plus | F4: uncharacterized protein conserved in bacteria | G4: yaaA | I4: protein-coding | L4: CCB94400.1 | M4: uncharacterized protein conserved in bacteria | N4: 63 | O4: SALIVA_0003
A5: FR873482.1 | B5: 3212 | C5: 4327 | E5: plus | F5: GTP-dependent nucleic acid-binding protein | G5: engD | I5: protein-coding | L5: CCB94401.1 | M5: GTP-dependent nucleic acid-binding protein | N5: 371 | O5: SALIVA_0004
A6: FR873482.1 | B6: 4400 | C6: 4969 | E6: plus | F6: peptidyl-tRNA hydrolase (PTH) | G6: pth | I6: protein-coding | L6: CCB94402.1 | M6: peptidyl-tRNA hydrolase (PTH) | N6: 189 | O6: SALIVA_0005
A7: FR873482.1 | B7: 4962 | C7: 8468 | E7: plus | F7: transcription-repair coupling factor | G7: trcF | I7: protein-coding | L7: CCB94403.1 | M7: transcription-repair coupling factor | N7: 1168 | O7: SALIVA_0006
A8: FR873482.1 | B8: 8654 | C8: 8929 | E8: plus | F8: S4 RNA-binding domain protein | G8: yaab | I8: protein-coding | L8: CCB94404.1 | M8: S4 RNA-binding domain protein | N8: 91 | O8: SALIVA_0007
A9: FR873482.1 | B9: 8913 | C9: 9284 | E9: plus | F9: putative cell-cycle protein, MesJ/Ycf62 family | G9: divIC | I9: protein-coding | L9: CCB94405.1 | M9: putative cell-cycle protein, MesJ/Ycf62 family | N9: 123 | O9: SALIVA_0008
A10: FR873482.1 | B10: 9284 | C10: 9415 | E10: plus | F10: uncharacterized conserved protein | G10: yaaC | I10: protein-coding | L10: CCB94406.1 | M10: uncharacterized conserved protein | N10: 43 | O10: SALIVA_0009
A11: FR873482.1 | B11: 9412 | C11: 10704 | E11: plus | F11: hypothetical protein | G11: yaaD | I11: protein-coding | L11: CCB94407.1 | M11: hypothetical protein | N11: 430 | O11: SALIVA_0010
A12: FR873482.1 | B12: 10704 | C12: 11969 | E12: plus | F12: tRNA(Ile)-lysidine synthase (tRNA(Ile)-lysidine synthetase) (tRNA(Ile)-2-lysyl-cytidine synthase) | G12: tilS | I12: protein-coding | L12: CCB94408.1 | M12: tRNA(Ile)-lysidine synthase (tRNA(Ile)-lysidine synthetase) (tRNA(Ile)-2-lysyl-cytidine synthase) | N12: 421 | O12: SALIVA_0011
A13: FR873482.1 | B13: 12051 | C13: 12593 | E13: plus | F13: hypoxanthine-guanine phosphoribosyltransferase (HGPRT) (HGPRTase) | G13: hpt | I13: protein-coding | L13: CCB94409.1 | M13: hypoxanthine-guanine phosphoribosyltransferase (HGPRT) (HGPRTase) | N13: 180 | O13: SALIVA_0012
A14: FR873482.1 | B14: 12613 | C14: 14592 | E14: plus | F14: cell division protein | G14: ftsH | I14: protein-coding | L14: CCB94410.1 | M14: cell division protein | N14: 659 | O14: SALIVA_0013
A15: FR873482.1 | B15: 14961 | C15: 16496 | E15: plus | F15: 16S ribosomal RNA | G15: 16S rRNA | I15: rRNA | O15: SALIVA_r0001
A16: FR873482.1 | B16: 16556 | C16: 16628 | E16: plus | F16: tRNA-Ala | I16: tRNA | O16: SALIVA_0014
A17: FR873482.1 | B17: 16777 | C17: 19674 | E17: plus | F17: 23S ribosomal RNA | G17: 23S rRNA | I17: rRNA | O17: SALIVA_r0002
A18: FR873482.1 | B18: 19761 | C18: 19904 | E18: plus | F18: 5S ribosomal RNA | G18: 5S rRNA | I18: rRNA | O18: SALIVA_r0003
A19: FR873482.1 | B19: 19879 | C19: 19951 | E19: plus | F19: tRNA-Val | I19: tRNA | O19: SALIVA_0015
A20: FR873482.1 | B20: 19954 | C20: 20029 | E20: plus | F20: tRNA-Asp | I20: tRNA | O20: SALIVA_0016
A21: FR873482.1 | B21: 20045 | C21: 20117 | E21: plus | F21: tRNA-Lys | I21: tRNA | O21: SALIVA_0017
A22: FR873482.1 | B22: 20123 | C22: 20204 | E22: plus | F22: tRNA-Leu | I22: tRNA | O22: SALIVA_0018
A23: FR873482.1 | B23: 20217 | C23: 20289 | E23: plus | F23: tRNA-Thr | I23: tRNA | O23: SALIVA_0019
A24: FR873482.1 | B24: 20296 | C24: 20367 | E24: plus | F24: tRNA-Gly | I24: tRNA | O24: SALIVA_0020
A25: FR873482.1 | B25: 20374 | C25: 20459 | E25: plus | F25: tRNA-Leu | I25: tRNA | O25: SALIVA_0021
A26: FR873482.1 | B26: 20474 | C26: 20547 | E26: plus | F26: tRNA-Arg | I26: tRNA | O26: SALIVA_0022
A27: FR873482.1 | B27: 20554 | C27: 20627 | E27: plus | F27: tRNA-Pro | I27: tRNA | O27: SALIVA_0023
A28: FR873482.1 | B28: 20633 | C28: 20706 | E28: plus | F28: tRNA-Met | I28: tRNA | O28: SALIVA_0024
A29: FR873482.1 | B29: 20723 | C29: 20796 | E29: plus | F29: tRNA-Met | I29: tRNA | O29: SALIVA_0025
A30: FR873482.1 | B30: 20816 | C30: 20905 | E30: plus | F30: tRNA-Ser | I30: tRNA | O30: SALIVA_0026
... A35: FR873482.1 | B35: 21254 | C35: 21341 | E35: plus | F35: tRNA-Ser | I35: tRNA | O35: SALIVA_0031
A36: FR873482.1 | B36: 21400 | C36: 22230 | E36: plus | F36: rod shape-determining protein MreC | G36: mreC | I36: protein-coding | L36: CCB94411.1 | M36: rod shape-determining protein MreC | N36: 276 | O36: SALIVA_0032
A37: FR873482.1 | B37: 22232 | C37: 22756 | E37: plus | F37: rod shape-determining protein MreD | G37: mreD | I37: protein-coding | L37: CCB94412.1 | M37: rod shape-determining protein MreD | N37: 174 | O37: SALIVA_0033
A38: FR873482.1 | B38: 22841 | C38: 24340 | E38: plus | F38: glucan binding protein | G38: pcsB | I38: protein-coding | L38: CCB94413.1 | M38: glucan binding protein | N38: 499 | O38: SALIVA_0034
A39: FR873482.1 | B39: 24552 | C39: 25517 | E39: plus | F39: ribose-phosphate pyrophosphokinase | G39: prsA1 | I39: protein-coding | L39: CCB94414.1 | M39: ribose-phosphate pyrophosphokinase | N39: 321 | O39: SALIVA_0035
A40: FR873482.1 | B40: 25610 | C40: 26785 | E40: plus | F40: aromatic amino acid aminotransferase | G40: araT | I40: protein-coding | L40: CCB94415.1 | M40: aromatic amino acid aminotransferase | N40: 391 | O40: SALIVA_0036
A41: FR873482.1 | B41: 26772 | C41: 27545 | E41: plus | F41: DNA repair protein recO (Recombination protein O) | G41: recO | I41: protein-coding | L41: CCB94416.1 | M41: DNA repair protein recO (Recombination protein O) | N41: 257 | O41: SALIVA_0037
A42: FR873482.1 | B42: 27757 | C42: 28761 | E42: plus | F42: fatty acid/phospholipid synthesis protein plsX | G42: plsX | I42: protein-coding | L42: CCB94417.1 | M42: fatty acid/phospholipid synthesis protein plsX | N42: 334 | O42: SALIVA_0038
A43: FR873482.1 | B43: 28761 | C43: 29006 | E43: plus | F43: acyl carrier protein | G43: acpP1 | I43: protein-coding | L43: CCB94418.1 | M43: acyl carrier protein | N43: 81 | O43: SALIVA_0039
A44: FR873482.1 | B44: 29265 | C44: 29972 | E44: plus | F44: phosphoribosylaminoimidazole-succinocarboxamide synthase (SAICAR synthetase) | G44: purC | I44: protein-coding | L44: CCB94419.1 | M44: phosphoribosylaminoimidazole-succinocarboxamide synthase (SAICAR synthetase) | N44: 235 | O44: SALIVA_0040
...

Sheet EC number
A1: Protein assession | B1: Locus tag | C1: EC number | D1: KEGG Enzyme URL | E1: KEGG Reaction URL | F1: Reactants | G1: Products
A2: CCB94535.1 | B2: SALIVA_0184 | C2: 1.-.-.-
A3: CCB94939.1 | B3: SALIVA_0612 | C3: 1.-.-.-
A4: CCB95136.1 | B4: SALIVA_0813 | C4: 1.-.-.-
A5: CCB95147.1 | B5: SALIVA_0825 | C5: 1.-.-.-
A6: CCB95183.1 | B6: SALIVA_0862 | C6: 1.-.-.-
A7: CCB95477.1 | B7: SALIVA_1163 | C7: 1.-.-.-
A8: CCB95687.1 | B8: SALIVA_1377 | C8: 1.-.-.-
A9: CCB95704.1 | B9: SALIVA_1393 | C9: 1.-.-.-
A10: CCB95726.1 | B10: SALIVA_1415 | C10: 1.-.-.-
A11: CCB96194.1 | B11: SALIVA_1899 | C11: 1.-.-.-
A12: CCB94764.1 | B12: SALIVA_0428 | C12: 1.1.-.-
A13: CCB95708.1 | B13: SALIVA_1397 | C13: 1.1.-.-
... A16: CCB95381.1 | B16: SALIVA_1066 | C16: 1.1.1.-
A17: CCB95454.1 | B17: SALIVA_1140 | C17: 1.1.1.1 | D17: https://www.genome.jp/entry/ec:1.1.1.1 | E17: https://www.genome.jp/entry/R00623 | F17: C00226|C00003 | G17: C00071|C00004|C00080
A18: CCB95454.1 | B18: SALIVA_1140 | C18: 1.1.1.1 | D18: https://www.genome.jp/entry/ec:1.1.1.1 | E18: https://www.genome.jp/entry/R00754 | F18: C00469|C00003 | G18: C00084|C00004|C00080
A19: CCB95454.1 | B19: SALIVA_1140 | C19: 1.1.1.1 | D19: https://www.genome.jp/entry/ec:1.1.1.1 | E19: https://www.genome.jp/entry/R02124 | F19: C00473|C00003 | G19: C00376|C00004|C00080
A20: CCB95454.1 | B20: SALIVA_1140 | C20: 1.1.1.1 | D20: https://www.genome.jp/entry/ec:1.1.1.1 | E20: https://www.genome.jp/entry/R02878 | F20: C00756|C00003 | G20: C01545|C00004|C00080
A21: CCB95454.1 | B21: SALIVA_1140 | C21: 1.1.1.1 | D21: https://www.genome.jp/entry/ec:1.1.1.1 | E21: https://www.genome.jp/entry/R04805 | F21: C05444|C00003 | G21: C05445|C00004|C00080
A22: CCB95454.1 | B22: SALIVA_1140 | C22: 1.1.1.1 | D22: https://www.genome.jp/entry/ec:1.1.1.1 | E22: https://www.genome.jp/entry/R04880 | F22: C05576|C00003 | G22: C05577|C00004|C00080
A23: CCB95454.1 | B23: SALIVA_1140 | C23: 1.1.1.1 | D23: https://www.genome.jp/entry/ec:1.1.1.1 | E23: https://www.genome.jp/entry/R05233 | F23: C06611|C00003 | G23: C06613|C00004|C00080
A24: CCB95454.1 | B24: SALIVA_1140 | C24: 1.1.1.1 | D24: https://www.genome.jp/entry/ec:1.1.1.1 | E24: https://www.genome.jp/entry/R05234 | F24: C06612|C00003 | G24: C16348|C00004|C00080
A25: CCB95454.1 | B25: SALIVA_1140 | C25: 1.1.1.1 | D25: https://www.genome.jp/entry/ec:1.1.1.1 | E25: https://www.genome.jp/entry/R06917 | F25: C14089|C00003 | G25: C14090|C00004|C00080
A26: CCB95454.1 | B26: SALIVA_1140 | C26: 1.1.1.1 | D26: https://www.genome.jp/entry/ec:1.1.1.1 | E26: https://www.genome.jp/entry/ R06927 | F26: C02909|C00003 | G26: C14099|C00004|C00080
A27: CCB95454.1 | B27: SALIVA_1140 | C27: 1.1.1.1 | D27: https://www.genome.jp/entry/ec:1.1.1.1 | E27: https://www.genome.jp/entry/ R08306 | F27: C16586|C00003 | G27: C16587|C00004|C00080
A28: CCB95454.1 | B28: SALIVA_1140 | C28: 1.1.1.1 | D28: https://www.genome.jp/entry/ec:1.1.1.1 | E28: https://www.genome.jp/entry/R08557 | F28: C00114|C00003 | G28: C00576|C00004|C00080
... A81: CCB95882.1 | B81: SALIVA_1575 | C81: 1.1.1.95 | D81: https://www.genome.jp/entry/ec:1.1.1.95 | E81: https://www.genome.jp/entry/R08198 | F81: C02630|C00003 | G81: C00026|C00004|C00080
A82: CCB95420.1 | B82: SALIVA_1106 | C82: 1.11.1.-
A83: CCB94457.1 | B83: SALIVA_0093 | C83: 1.11.1.15
A84: CCB95682.1 | B84: SALIVA_1372 | C84: 1.11.1.9 | D84: https://www.genome.jp/entry/ec:1.11.1.9 | E84: https://www.genome.jp/entry/R00274 | F84: C00027|C00051 | G84: C00127|C00001
A85: CCB95371.1 | B85: SALIVA_1056 | C85: 1.14.13.-
A86: CCB95100.1 | B86: SALIVA_0774 | C86: 1.15.1.1 | D86: https://www.genome.jp/entry/ec:1.15.1.1 | E86: https://www.genome.jp/entry/R00275 | F86: C00704|C00080 | G86: C00027|C00007
A87: CCB95103.1 | B87: SALIVA_0778 | C87: 1.16.-.-
A88: CCB94736.1 | B88: SALIVA_0398 | C88: 1.17.1.8 | D88: https://www.genome.jp/entry/ec:1.17.1.8 | E88: https://www.genome.jp/entry/R04198 | F88: C03972|C00003|C00001 | G88: C20258|C00004|C00080
A89: CCB94736.1 | B89: SALIVA_0398 | C89: 1.17.1.8 | D89: https://www.genome.jp/entry/ec:1.17.1.8 | E89: https://www.genome.jp/entry/R04199 | F89: C03972|C00006|C00001 | G89: C20258|C00005|C00080
A90: CCB95120.1 | B90: SALIVA_0797 | C90: 1.17.4.1 | D90: https://www.genome.jp/entry/ec:1.17.4.1 | E90: https://www.genome.jp/entry/R04294 | F90: C04232|C00343|C00001 | G90: C03723|C00342
A91: CCB95120.1 | B91: SALIVA_0797 | C91: 1.17.4.1 | D91: https://www.genome.jp/entry/ec:1.17.4.1 | E91: https://www.genome.jp/entry/R02017 | F91: C00206|C00343|C00001 | G91: C00342|C00008
A92: CCB95120.1 | B92: SALIVA_0797 | C92: 1.17.4.1 | D92: https://www.genome.jp/entry/ec:1.17.4.1 | E92: https://www.genome.jp/entry/R02018 | F92: C01346|C00343|C00001 | G92: C00342|C00015
A93: CCB95120.1 | B93: SALIVA_0797 | C93: 1.17.4.1 | D93: https://www.genome.jp/entry/ec:1.17.4.1 | E93: https://www.genome.jp/entry/R02019 | F93: C00361|C00343|C00001 | G93: C00035|C00342
A94: CCB95120.1 | B94: SALIVA_0797 | C94: 1.17.4.1 | D94: https://www.genome.jp/entry/ec:1.17.4.1 | E94: https://www.genome.jp/entry/R02024 | F94: C00705|C00343|C00001 | G94: C00342|C00112
...

Sheet Metabolites
A1: Metabolites | B1: Name | C1: Initial Concentration (mM) | D1: Object
A2: C00001 | B2: H2O | C2: =CONCATENATE(A2,":","1000") -> C00001:1000 | D2: =CONCATENATE(A2," : ",B2) -> C00001 : H2O
A3: C00002 | B3: ATP | C3: =CONCATENATE(A3,":","1000") -> C00002:1000 | D3: =CONCATENATE(A3," : ",B3) -> C00002 : ATP
A4: C00003 | B4: NAD+ | C4: =CONCATENATE(A4,":","1000") -> C00003:1000 | D4: =CONCATENATE(A4," : ",B4) -> C00003 : NAD+
A5: C00004 | B5: NADH | C5: =CONCATENATE(A5,":","1000") -> C00004:1000 | D5: =CONCATENATE(A5," : ",B5) -> C00004 : NADH
A6: C00005 | B6: NADPH | C6: =CONCATENATE(A6,":","1000") -> C00005:1000 | D6: =CONCATENATE(A6," : ",B6) -> C00005 : NADPH
A7: C00006 | B7: NADP+ | C7: =CONCATENATE(A7,":","1000") -> C00006:1000 | D7: =CONCATENATE(A7," : ",B7) -> C00006 : NADP+
A8: C00007 | B8: Oxygen | C8: =CONCATENATE(A8,":","1000") -> C00007:1000 | D8: =CONCATENATE(A8," : ",B8) -> C00007 : Oxygen
A9: C00008 | B9: ADP | C9: =CONCATENATE(A9,":","1000") -> C00008:1000 | D9: =CONCATENATE(A9," : ",B9) -> C00008 : ADP
A10: C00009 | B10: Orthophosphate | C10: =CONCATENATE(A10,":","1000") -> C00009:1000 | D10: =CONCATENATE(A10," : ",B10) -> C00009 : Orthophosphate
A11: C00010 | B11: CoA | C11: =CONCATENATE(A11,":","1000") -> C00010:1000 | D11: =CONCATENATE(A11," : ",B11) -> C00010 : CoA
A12: C00011 | B12: CO2 | C12: =CONCATENATE(A12,":","1000") -> C00011:1000 | D12: =CONCATENATE(A12," : ",B12) -> C00011 : CO2
A13: C00013 | B13: Diphosphate | C13: =CONCATENATE(A13,":","1000") -> C00013:1000 | D13: =CONCATENATE(A13," : ",B13) -> C00013 : Diphosphate
... A16: C00016 | B16: FAD | C16: =CONCATENATE(A16,":","1000") -> C00016:1000 | D16: =CONCATENATE(A16," : ",B16) -> C00016 : FAD
A17: C00017 | B17: Protein | C17: =CONCATENATE(A17,":","1") -> C00017:1 | D17: =CONCATENATE(A17," : ",B17) -> C00017 : Protein
A18: C00018 | B18: Pyridoxal phosphate | C18: =CONCATENATE(A18,":","1") -> C00018:1 | D18: =CONCATENATE(A18," : ",B18) -> C00018 : Pyridoxal phosphate
A19: C00019 | B19: S-Adenosyl-L-methionine | C19: =CONCATENATE(A19,":","1000") -> C00019:1000 | D19: =CONCATENATE(A19," : ",B19) -> C00019 : S-Adenosyl-L-methionine
A20: C00020 | B20: AMP | C20: =CONCATENATE(A20,":","1000") -> C00020:1000 | D20: =CONCATENATE(A20," : ",B20) -> C00020 : AMP
A21: C00021 | B21: S-Adenosyl-L-homocysteine | C21: =CONCATENATE(A21,":","1000") -> C00021:1000 | D21: =CONCATENATE(A21," : ",B21) -> C00021 : S-Adenosyl-L-homocysteine
A22: C00022 | B22: Pyruvate | C22: =CONCATENATE(A22,":","1000") -> C00022:1000 | D22: =CONCATENATE(A22," : ",B22) -> C00022 : Pyruvate
A23: C00024 | B23: Acetyl-CoA | C23: =CONCATENATE(A23,":","1000") -> C00024:1000 | D23: =CONCATENATE(A23," : ",B23) -> C00024 : Acetyl-CoA
A24: C00025 | B24: L-Glutamate | C24: =CONCATENATE(A24,":","1000") -> C00025 :1000 | D24: =CONCATENATE(A24," : ",B24) -> C00025 : L-Glutamate
A25: C00026 | B25: 2-Oxoglutarate | C25: =CONCATENATE(A25,":","1") -> C00026:1 | D25: =CONCATENATE(A25," : ",B25) -> C00026 : 2-Oxoglutarate
A26: C00027 | B26: Hydrogen peroxide | C26: =CONCATENATE(A26,":","1") -> C00027:1 | D26: =CONCATENATE(A26," : ",B26) -> C00027 : Hydrogen peroxide
A27: C00029 | B27: UDP-glucose | C27: =CONCATENATE(A27,":","1000") -> C00029:1000 | D27: =CONCATENATE(A27," : ",B27) -> C00029 : UDP-glucose
A28: C00031 | B28: D-Glucose | C28: =CONCATENATE(A28,":","1000") -> C00031 :1000 | D28: =CONCATENATE(A28," : ",B28) -> C00031 : D-Glucose
A29: C00033 | B29: Acetate | C29: =CONCATENATE(A29,":","1") -> C00033:1 | D29: =CONCATENATE(A29," : ",B29) -> C00033 : Acetate
A30: C00035 | B30: GDP | C30: =CONCATENATE(A30,":","1000") -> C00035:1000 | D30: =CONCATENATE(A30," : ",B30) -> C00035 : GDP
A31: C00036 | B31: Oxaloacetate | C31: =CONCATENATE(A31,":","1") -> C00036:1 | D31: =CONCATENATE(A31," : ",B31) -> C00036 : Oxaloacetate
A32: C00037 | B32: Glycine | C32: =CONCATENATE(A32,":","1000") -> C00037:1000 | D32: =CONCATENATE(A32," : ",B32) -> C00037 : Glycine
A33: C00039 | B33: DNA | C33: =CONCATENATE(A33,":","1") -> C00039:1 | D33: =CONCATENATE(A33," : ",B33) -> C00039 : DNA
A34: C00040 | B34: Acyl-CoA | C34: =CONCATENATE(A34,":","1") -> C00040:1 | D34: =CONCATENATE(A34," : ",B34) -> C00040 : Acyl-CoA
A35: C00041 | B35: L-Alanine | C35: =CONCATENATE(A35,":","1000") -> C00041:1000 | D35: =CONCATENATE(A35," : ",B35) -> C00041 : L-Alanine
A36: C00042 | B36: Succinate | C36: =CONCATENATE(A36,":","1") -> C00042:1 | D36: =CONCATENATE(A36," : ",B36) -> C00042 : Succinate
A37: C00043 | B37: UDP-N-acetyl-alpha-D-glucosamine | C37: =CONCATENATE(A37,":","1") -> C00043:1 | D37: =CONCATENATE(A37," : ",B37) -> C00043 : UDP-N-acetyl-alpha-D-glucosamine
A38: C00044 | B38: GTP | C38: =CONCATENATE(A38,":","1") -> C00044:1 | D38: =CONCATENATE(A38," : ",B38) -> C00044 : GTP
A39: C00046 | B39: RNA | C39: =CONCATENATE(A39,":","1") -> C00046:1 | D39: =CONCATENATE(A39," : ",B39) -> C00046 : RNA
A40: C00047 | B40: L-Lysine | C40: =CONCATENATE(A40,":","1000") -> C00047:1000 | D40: =CONCATENATE(A40," : ",B40) -> C00047 : L-Lysine
A41: C00048 | B41: Glyoxylate | C41: =CONCATENATE(A41,":","1") -> C00048:1 | D41: =CONCATENATE(A41," : ",B41) -> C00048 : Glyoxylate
A42: C00049 | B42: L-Aspartate | C42: =CONCATENATE(A42,":","1000") -> C00049:1000 | D42: =CONCATENATE(A42," : ",B42) -> C00049 : L-Aspartate
...

Sheet Enzymes
A1: No. | B1: EC number | C1: Enztmes mRNA | D1: Enzymes | E1: Enzymes Turnover (/s) | F1: Enzymes Km (mM) | G1: Enzyme mRNA Objects | H1: Enzyme Objects | I1: Enzyme mRNA Initial Concentration (mM) | J1: Enzyme Initial Concentration (Mm) | K1: Translation Rate Law | L1: Translation Rate Law | M1: Transcription Equation | N1: Translation Equation
A2: 1 | B2: 1_1_1_1 | C2: =CONCATENATE(D2,"_mRNA") -> E1_1_1_1_mRNA | D2: =CONCATENATE("E",B2) -> E1_1_1_1 | E2: =CONCATENATE("E",B2,"_kcat : 13.7") -> E1_1_1_1_kcat : 13.7 | F2: =CONCATENATE("E",B2,"_km : 1") -> E1_1_1_1_km : 1 | G2: =CONCATENATE(C2," : ",C2) -> E1_1_1_1_mRNA : E1_1_1_1_mRNA | H2: =CONCATENATE(D2," : ",D2) -> E1_1_1_1 : E1_1_1_1 | I2: =CONCATENATE(C2," : ","0") -> E1_1_1_1_mRNA : 0 | J2: =CONCATENATE(D2," : ","0") -> E1_1_1_1 : 0 | K2: =CONCATENATE("0.00292 - (0.0093 * ",C2,")") -> 0.00292 - (0.0093 * E1_1_1_1_mRNA) | L2: =CONCATENATE("(0.278 * ",C2,")"," - (0.00000278 * ",D2,")") -> (0.278 * E1_1_1_1_mRNA) - (0.00000278 * E1_1_1_1) | M2: =CONCATENATE("mRNA",A2,": -> ",C2," | ","0.00292"," - ","(","0.0093"," * ",C2,")") -> mRNA1: -> E1_1_1_1_mRNA | 0.00292 - (0.0093 * E1_1_1_1_mRNA) | N2: =CONCATENATE("Peptide",A2,": ",C2," -> ",D2," | ","(","0.278"," * ",C2,")"," - ","(","0.000000278"," * ",D2,")") -> Peptide1: E1_1_1_1_mRNA -> E1_1_1_1 | (0.278 * E1_1_1_1_mRNA) - (0.000000278 * E1_1_1_1)
A3: 2 | B3: 1_1_1_100 | C3: =CONCATENATE(D3,"_mRNA") -> E1_1_1_100_mRNA | D3: =CONCATENATE("E",B3) -> E1_1_1_100 | E3: =CONCATENATE("E",B3,"_kcat : 13.7") -> E1_1_1_100_kcat : 13.7 | F3: =CONCATENATE("E",B3,"_km : 1") -> E1_1_1_100_km : 1 | G3: =CONCATENATE(C3," : ",C3) -> E1_1_1_100_mRNA : E1_1_1_100_mRNA | H3: =CONCATENATE(D3," : ",D3) -> E1_1_1_100 : E1_1_1_100 | I3: =CONCATENATE(C3," : ","0") -> E1_1_1_100_mRNA : 0 | J3: =CONCATENATE(D3," : ","0") -> E1_1_1_100 : 0 | K3: =CONCATENATE("0.00292 - (0.0093 * ",C3,")") -> 0.00292 - (0.0093 * E1_1_1_100_mRNA) | L3: =CONCATENATE("(0.278 * ",C3,")"," - (0.00000278 * ",D3,")") -> (0.278 * E1_1_1_100_mRNA) - (0.00000278 * E1_1_1_100) | M3: =CONCATENATE("mRNA",A3,": -> ",C3," | ","0.00292"," - ","(","0.0093"," * ",C3,")") -> mRNA2: -> E1_1_1_100_mRNA | 0.00292 - (0.0093 * E1_1_1_100_mRNA) | N3: =CONCATENATE("Peptide",A3,": ",C3," -> ",D3," | ","(","0.278"," * ",C3,")"," - ","(","0.000000278"," * ",D3,")") -> Peptide2: E1_1_1_100_mRNA -> E1_1_1_100 | (0.278 * E1_1_1_100_mRNA) - (0.000000278 * E1_1_1_100)
A4: 3 | B4: 1_1_1_133 | C4: =CONCATENATE(D4,"_mRNA") -> E1_1_1_133_mRNA | D4: =CONCATENATE("E",B4) -> E1_1_1_133 | E4: =CONCATENATE("E",B4,"_kcat : 13.7") -> E1_1_1_133_kcat : 13.7 | F4: =CONCATENATE("E",B4,"_km : 1") -> E1_1_1_133_km : 1 | G4: =CONCATENATE(C4," : ",C4) -> E1_1_1_133_mRNA : E1_1_1_133_mRNA | H4: =CONCATENATE(D4," : ",D4) -> E1_1_1_133 : E1_1_1_133 | I4: =CONCATENATE(C4," : ","0") -> E1_1_1_133_mRNA : 0 | J4: =CONCATENATE(D4," : ","0") -> E1_1_1_133 : 0 | K4: =CONCATENATE("0.00292 - (0.0093 * ",C4,")") -> 0.00292 - (0.0093 * E1_1_1_133_mRNA) | L4: =CONCATENATE("(0.278 * ",C4,")"," - (0.00000278 * ",D4,")") -> (0.278 * E1_1_1_133_mRNA) - (0.00000278 * E1_1_1_133) | M4: =CONCATENATE("mRNA",A4,": -> ",C4," | ","0.00292"," - ","(","0.0093"," * ",C4,")") -> mRNA3: -> E1_1_1_133_mRNA | 0.00292 - (0.0093 * E1_1_1_133_mRNA) | N4: =CONCATENATE("Peptide",A4,": ",C4," -> ",D4," | ","(","0.278"," * ",C4,")"," - ","(","0.000000278"," * ",D4,")") -> Peptide3: E1_1_1_133_mRNA -> E1_1_1_133 | (0.278 * E1_1_1_133_mRNA) - (0.000000278 * E1_1_1_133)
A5: 4 | B5: 1_1_1_14 | C5: =CONCATENATE(D5,"_mRNA") -> E1_1_1_14_mRNA | D5: =CONCATENATE("E",B5) -> E1_1_1_14 | E5: =CONCATENATE("E",B5,"_kcat : 13.7") -> E1_1_1_14_kcat : 13.7 | F5: =CONCATENATE("E",B5,"_km : 1") -> E1_1_1_14_km : 1 | G5: =CONCATENATE(C5," : ",C5) -> E1_1_1_14_mRNA : E1_1_1_14_mRNA | H5: =CONCATENATE(D5," : ",D5) -> E1_1_1_14 : E1_1_1_14 | I5: =CONCATENATE(C5," : ","0") -> E1_1_1_14_mRNA : 0 | J5: =CONCATENATE(D5," : ","0") -> E1_1_1_14 : 0 | K5: =CONCATENATE("0.00292 - (0.0093 * ",C5,")") -> 0.00292 - (0.0093 * E1_1_1_14_mRNA) | L5: =CONCATENATE("(0.278 * ",C5,")"," - (0.00000278 * ",D5,")") -> (0.278 * E1_1_1_14_mRNA) - (0.00000278 * E1_1_1_14) | M5: =CONCATENATE("mRNA",A5,": -> ",C5," | ","0.00292"," - ","(","0.0093"," * ",C5,")") -> mRNA4: -> E1_1_1_14_mRNA | 0.00292 - (0.0093 * E1_1_1_14_mRNA) | N5: =CONCATENATE("Peptide",A5,": ",C5," -> ",D5," | ","(","0.278"," * ",C5,")"," - ","(","0.000000278"," * ",D5,")") -> Peptide4: E1_1_1_14_mRNA -> E1_1_1_14 | (0.278 * E1_1_1_14_mRNA) - (0.000000278 * E1_1_1_14)
A6: 5 | B6: 1_1_1_170 | C6: =CONCATENATE(D6,"_mRNA") -> E1_1_1_170_mRNA | D6: =CONCATENATE("E",B6) -> E1_1_1_170 | E6: =CONCATENATE("E",B6,"_kcat : 13.7") -> E1_1_1_170_kcat : 13.7 | F6: =CONCATENATE("E",B6,"_km : 1") -> E1_1_1_170_km : 1 | G6: =CONCATENATE(C6," : ",C6) -> E1_1_1_170_mRNA : E1_1_1_170_mRNA | H6: =CONCATENATE(D6," : ",D6) -> E1_1_1_170 : E1_1_1_170 | I6: =CONCATENATE(C6," : ","0") -> E1_1_1_170_mRNA : 0 | J6: =CONCATENATE(D6," : ","0") -> E1_1_1_170 : 0 | K6: =CONCATENATE("0.00292 - (0.0093 * ",C6,")") -> 0.00292 - (0.0093 * E1_1_1_170_mRNA) | L6: =CONCATENATE("(0.278 * ",C6,")"," - (0.00000278 * ",D6,")") -> (0.278 * E1_1_1_170_mRNA) - (0.00000278 * E1_1_1_170) | M6: =CONCATENATE("mRNA",A6,": -> ",C6," | ","0.00292"," - ","(","0.0093"," * ",C6,")") -> mRNA5: -> E1_1_1_170_mRNA | 0.00292 - (0.0093 * E1_1_1_170_mRNA) | N6: =CONCATENATE("Peptide",A6,": ",C6," -> ",D6," | ","(","0.278"," * ",C6,")"," - ","(","0.000000278"," * ",D6,")") -> Peptide5: E1_1_1_170_mRNA -> E1_1_1_170 | (0.278 * E1_1_1_170_mRNA) - (0.000000278 * E1_1_1_170)
A7: 6 | B7: 1_1_1_205 | C7: =CONCATENATE(D7,"_mRNA") -> E1_1_1_205_mRNA | D7: =CONCATENATE("E",B7) -> E1_1_1_205 | E7: =CONCATENATE("E",B7,"_kcat : 13.7") -> E1_1_1_205_kcat : 13.7 | F7: =CONCATENATE("E",B7,"_km : 1") -> E1_1_1_205_km : 1 | G7: =CONCATENATE(C7," : ",C7) -> E1_1_1_205_mRNA : E1_1_1_205_mRNA | H7: =CONCATENATE(D7," : ",D7) -> E1_1_1_205 : E1_1_1_205 | I7: =CONCATENATE(C7," : ","0") -> E1_1_1_205_mRNA : 0 | J7: =CONCATENATE(D7," : ","0") -> E1_1_1_205 : 0 | K7: =CONCATENATE("0.00292 - (0.0093 * ",C7,")") -> 0.00292 - (0.0093 * E1_1_1_205_mRNA) | L7: =CONCATENATE("(0.278 * ",C7,")"," - (0.00000278 * ",D7,")") -> (0.278 * E1_1_1_205_mRNA) - (0.00000278 * E1_1_1_205) | M7: =CONCATENATE("mRNA",A7,": -> ",C7," | ","0.00292"," - ","(","0.0093"," * ",C7,")") -> mRNA6: -> E1_1_1_205_mRNA | 0.00292 - (0.0093 * E1_1_1_205_mRNA) | N7: =CONCATENATE("Peptide",A7,": ",C7," -> ",D7," | ","(","0.278"," * ",C7,")"," - ","(","0.000000278"," * ",D7,")") -> Peptide6: E1_1_1_205_mRNA -> E1_1_1_205 | (0.278 * E1_1_1_205_mRNA) - (0.000000278 * E1_1_1_205)
A8: 7 | B8: 1_1_1_23 | C8: =CONCATENATE(D8,"_mRNA") -> E1_1_1_23_mRNA | D8: =CONCATENATE("E",B8) -> E1_1_1_23 | E8: =CONCATENATE("E",B8,"_kcat : 13.7") -> E1_1_1_23_kcat : 13.7 | F8: =CONCATENATE("E",B8,"_km : 1") -> E1_1_1_23_km : 1 | G8: =CONCATENATE(C8," : ",C8) -> E1_1_1_23_mRNA : E1_1_1_23_mRNA | H8: =CONCATENATE(D8," : ",D8) -> E1_1_1_23 : E1_1_1_23 | I8: =CONCATENATE(C8," : ","0") -> E1_1_1_23_mRNA : 0 | J8: =CONCATENATE(D8," : ","0") -> E1_1_1_23 : 0 | K8: =CONCATENATE("0.00292 - (0.0093 * ",C8,")") -> 0.00292 - (0.0093 * E1_1_1_23_mRNA) | L8: =CONCATENATE("(0.278 * ",C8,")"," - (0.00000278 * ",D8,")") -> (0.278 * E1_1_1_23_mRNA) - (0.00000278 * E1_1_1_23) | M8: =CONCATENATE("mRNA",A8,": -> ",C8," | ","0.00292"," - ","(","0.0093"," * ",C8,")") -> mRNA7: -> E1_1_1_23_mRNA | 0.00292 - (0.0093 * E1_1_1_23_mRNA) | N8: =CONCATENATE("Peptide",A8,": ",C8," -> ",D8," | ","(","0.278"," * ",C8,")"," - ","(","0.000000278"," * ",D8,")") -> Peptide7: E1_1_1_23_mRNA -> E1_1_1_23 | (0.278 * E1_1_1_23_mRNA) - (0.000000278 * E1_1_1_23)
A9: 8 | B9: 1_1_1_25 | C9: =CONCATENATE(D9,"_mRNA") -> E1_1_1_25_mRNA | D9: =CONCATENATE("E",B9) -> E1_1_1_25 | E9: =CONCATENATE("E",B9,"_kcat : 13.7") -> E1_1_1_25_kcat : 13.7 | F9: =CONCATENATE("E",B9,"_km : 1") -> E1_1_1_25_km : 1 | G9: =CONCATENATE(C9," : ",C9) -> E1_1_1_25_mRNA : E1_1_1_25_mRNA | H9: =CONCATENATE(D9," : ",D9) -> E1_1_1_25 : E1_1_1_25 | I9: =CONCATENATE(C9," : ","0") -> E1_1_1_25_mRNA : 0 | J9: =CONCATENATE(D9," : ","0") -> E1_1_1_25 : 0 | K9: =CONCATENATE("0.00292 - (0.0093 * ",C9,")") -> 0.00292 - (0.0093 * E1_1_1_25_mRNA) | L9: =CONCATENATE("(0.278 * ",C9,")"," - (0.00000278 * ",D9,")") -> (0.278 * E1_1_1_25_mRNA) - (0.00000278 * E1_1_1_25) | M9: =CONCATENATE("mRNA",A9,": -> ",C9," | ","0.00292"," - ","(","0.0093"," * ",C9,")") -> mRNA8: -> E1_1_1_25_mRNA | 0.00292 - (0.0093 * E1_1_1_25_mRNA) | N9: =CONCATENATE("Peptide",A9,": ",C9," -> ",D9," | ","(","0.278"," * ",C9,")"," - ","(","0.000000278"," * ",D9,")") -> Peptide8: E1_1_1_25_mRNA -> E1_1_1_25 | (0.278 * E1_1_1_25_mRNA) - (0.000000278 * E1_1_1_25)
A10: 9 | B10: 1_1_1_27 | C10: =CONCATENATE(D10,"_mRNA") -> E1_1_1_27_mRNA | D10: =CONCATENATE("E",B10) -> E1_1_1_27 | E10: =CONCATENATE("E",B10,"_kcat : 13.7") -> E1_1_1_27_kcat : 13.7 | F10: =CONCATENATE("E",B10,"_km : 1") -> E1_1_1_27_km : 1 | G10: =CONCATENATE(C10," : ",C10) -> E1_1_1_27_mRNA : E1_1_1_27_mRNA | H10: =CONCATENATE(D10," : ",D10) -> E1_1_1_27 : E1_1_1_27 | I10: =CONCATENATE(C10," : ","0") -> E1_1_1_27_mRNA : 0 | J10: =CONCATENATE(D10," : ","0") -> E1_1_1_27 : 0 | K10: =CONCATENATE("0.00292 - (0.0093 * ",C10,")") -> 0.00292 - (0.0093 * E1_1_1_27_mRNA) | L10: =CONCATENATE("(0.278 * ",C10,")"," - (0.00000278 * ",D10,")") -> (0.278 * E1_1_1_27_mRNA) - (0.00000278 * E1_1_1_27) | M10: =CONCATENATE("mRNA",A10,": -> ",C10," | ","0.00292"," - ","(","0.0093"," * ",C10,")") -> mRNA9: -> E1_1_1_27_mRNA | 0.00292 - (0.0093 * E1_1_1_27_mRNA) | N10: =CONCATENATE("Peptide",A10,": ",C10," -> ",D10," | ","(","0.278"," * ",C10,")"," - ","(","0.000000278"," * ",D10,")") -> Peptide9: E1_1_1_27_mRNA -> E1_1_1_27 | (0.278 * E1_1_1_27_mRNA) - (0.000000278 * E1_1_1_27)
A11: 10 | B11: 1_1_1_3 | C11: =CONCATENATE(D11,"_mRNA") -> E1_1_1_3_mRNA | D11: =CONCATENATE("E",B11) -> E1_1_1_3 | E11: =CONCATENATE("E",B11,"_kcat : 13.7") -> E1_1_1_3_kcat : 13.7 | F11: =CONCATENATE("E",B11,"_km : 1") -> E1_1_1_3_km : 1 | G11: =CONCATENATE(C11," : ",C11) -> E1_1_1_3_mRNA : E1_1_1_3_mRNA | H11: =CONCATENATE(D11," : ",D11) -> E1_1_1_3 : E1_1_1_3 | I11: =CONCATENATE(C11," : ","0") -> E1_1_1_3_mRNA : 0 | J11: =CONCATENATE(D11," : ","0") -> E1_1_1_3 : 0 | K11: =CONCATENATE("0.00292 - (0.0093 * ",C11,")") -> 0.00292 - (0.0093 * E1_1_1_3_mRNA) | L11: =CONCATENATE("(0.278 * ",C11,")"," - (0.00000278 * ",D11,")") -> (0.278 * E1_1_1_3_mRNA) - (0.00000278 * E1_1_1_3) | M11: =CONCATENATE("mRNA",A11,": -> ",C11," | ","0.00292"," - ","(","0.0093"," * ",C11,")") -> mRNA10: -> E1_1_1_3_mRNA | 0.00292 - (0.0093 * E1_1_1_3_mRNA) | N11: =CONCATENATE("Peptide",A11,": ",C11," -> ",D11," | ","(","0.278"," * ",C11,")"," - ","(","0.000000278"," * ",D11,")") -> Peptide10: E1_1_1_3_mRNA -> E1_1_1_3 | (0.278 * E1_1_1_3_mRNA) - (0.000000278 * E1_1_1_3)
A12: 11 | B12: 1_1_1_304 | C12: =CONCATENATE(D12,"_mRNA") -> E1_1_1_304_mRNA | D12: =CONCATENATE("E",B12) -> E1_1_1_304 | E12: =CONCATENATE("E",B12,"_kcat : 13.7") -> E1_1_1_304_kcat : 13.7 | F12: =CONCATENATE("E",B12,"_km : 1") -> E1_1_1_304_km : 1 | G12: =CONCATENATE(C12," : ",C12) -> E1_1_1_304_mRNA : E1_1_1_304_mRNA | H12: =CONCATENATE(D12," : ",D12) -> E1_1_1_304 : E1_1_1_304 | I12: =CONCATENATE(C12," : ","0") -> E1_1_1_304_mRNA : 0 | J12: =CONCATENATE(D12," : ","0") -> E1_1_1_304 : 0 | K12: =CONCATENATE("0.00292 - (0.0093 * ",C12,")") -> 0.00292 - (0.0093 * E1_1_1_304_mRNA) | L12: =CONCATENATE("(0.278 * ",C12,")"," - (0.00000278 * ",D12,")") -> (0.278 * E1_1_1_304_mRNA) - (0.00000278 * E1_1_1_304) | M12: =CONCATENATE("mRNA",A12,": -> ",C12," | ","0.00292"," - ","(","0.0093"," * ",C12,")") -> mRNA11: -> E1_1_1_304_mRNA | 0.00292 - (0.0093 * E1_1_1_304_mRNA) | N12: =CONCATENATE("Peptide",A12,": ",C12," -> ",D12," | ","(","0.278"," * ",C12,")"," - ","(","0.000000278"," * ",D12,")") -> Peptide11: E1_1_1_304_mRNA -> E1_1_1_304 | (0.278 * E1_1_1_304_mRNA) - (0.000000278 * E1_1_1_304)
A13: 12 | B13: 1_1_1_42 | C13: =CONCATENATE(D13,"_mRNA") -> E1_1_1_42_mRNA | D13: =CONCATENATE("E",B13) -> E1_1_1_42 | E13: =CONCATENATE("E",B13,"_kcat : 13.7") -> E1_1_1_42_kcat : 13.7 | F13: =CONCATENATE("E",B13,"_km : 1") -> E1_1_1_42_km : 1 | G13: =CONCATENATE(C13," : ",C13) -> E1_1_1_42_mRNA : E1_1_1_42_mRNA | H13: =CONCATENATE(D13," : ",D13) -> E1_1_1_42 : E1_1_1_42 | I13: =CONCATENATE(C13," : ","0") -> E1_1_1_42_mRNA : 0 | J13: =CONCATENATE(D13," : ","0") -> E1_1_1_42 : 0 | K13: =CONCATENATE("0.00292 - (0.0093 * ",C13,")") -> 0.00292 - (0.0093 * E1_1_1_42_mRNA) | L13: =CONCATENATE("(0.278 * ",C13,")"," - (0.00000278 * ",D13,")") -> (0.278 * E1_1_1_42_mRNA) - (0.00000278 * E1_1_1_42) | M13: =CONCATENATE("mRNA",A13,": -> ",C13," | ","0.00292"," - ","(","0.0093"," * ",C13,")") -> mRNA12: -> E1_1_1_42_mRNA | 0.00292 - (0.0093 * E1_1_1_42_mRNA) | N13: =CONCATENATE("Peptide",A13,": ",C13," -> ",D13," | ","(","0.278"," * ",C13,")"," - ","(","0.000000278"," * ",D13,")") -> Peptide12: E1_1_1_42_mRNA -> E1_1_1_42 | (0.278 * E1_1_1_42_mRNA) - (0.000000278 * E1_1_1_42)
... A365: 364 | B365: 6_4_1_2 | C365: =CONCATENATE(D365,"_mRNA") -> E6_4_1_2_mRNA | D365: =CONCATENATE("E",B365) -> E6_4_1_2 | E365: =CONCATENATE("E",B365,"_kcat : 13.7") -> E6_4_1_2_kcat : 13.7 | F365: =CONCATENATE("E",B365,"_km : 1") -> E6_4_1_2_km : 1 | G365: =CONCATENATE(C365," : ",C365) -> E6_4_1_2_mRNA : E6_4_1_2_mRNA | H365: =CONCATENATE(D365," : ",D365) -> E6_4_1_2 : E6_4_1_2 | I365: =CONCATENATE(C365," : ","0") -> E6_4_1_2_mRNA : 0 | J365: =CONCATENATE(D365," : ","0") -> E6_4_1_2 : 0 | K365: =CONCATENATE("0.00292 - (0.0093 * ",C365,")") -> 0.00292 - (0.0093 * E6_4_1_2_mRNA) | L365: =CONCATENATE("(0.278 * ",C365,")"," - (0.00000278 * ",D365,")") -> (0.278 * E6_4_1_2_mRNA) - (0.00000278 * E6_4_1_2) | M365: =CONCATENATE("mRNA",A365,": -> ",C365," | ","0.00292"," - ","(","0.0093"," * ",C365,")") -> mRNA364: -> E6_4_1_2_mRNA | 0.00292 - (0.0093 * E6_4_1_2_mRNA) | N365: =CONCATENATE("Peptide",A365,": ",C365," -> ",D365," | ","(","0.278"," * ",C365,")"," - ","(","0.000000278"," * ",D365,")") -> Peptide364: E6_4_1_2_mRNA -> E6_4_1_2 | (0.278 * E6_4_1_2_mRNA) - (0.000000278 * E6_4_1_2)

Sheet Reactions
A1: Protein assession | B1: Locus tag | C1: EC number | D1: No. | E1: Enzymes | F1: Reactants | G1: Reactants | H1: Products | I1: Products | J1: Rate Law | K1: Equation
A2: CCB95454.1 | B2: SALIVA_1140 | C2: 1_1_1_1 | D2: 1 | E2: =CONCATENATE("E",Reactions!C2) -> E1_1_1_1 | F2: C00226+C00003 | G2: C00226*C00003 | H2: C00071+C00004+C00080 | I2: C00071*C00004*C00080 | J2: =CONCATENATE("(${Variables:",E2,"_kcat","} * ",E2," * ",G2,")","/(${Variables:",E2,"_km","} + (",E2," * ",G2,"))") -> (${Variables:E1_1_1_1_kcat} * E1_1_1_1 * C00226*C00003)/(${Variables:E1_1_1_1_km} + (E1_1_1_1 * C00226*C00003)) | K2: =CONCATENATE("r",D2,": ",F2," -> ",H2," | ",J2) -> r1: C00226+C00003 -> C00071+C00004+C00080 | (${Variables:E1_1_1_1_kcat} * E1_1_1_1 * C00226*C00003)/(${Variables:E1_1_1_1_km} + (E1_1_1_1 * C00226*C00003))
A3: CCB95454.1 | B3: SALIVA_1140 | C3: 1_1_1_1 | D3: 2 | E3: =CONCATENATE("E",Reactions!C3) -> E1_1_1_1 | F3: C00469+C00003 | G3: C00469*C00003 | H3: C00084+C00004+C00080 | I3: C00084*C00004*C00080 | J3: =CONCATENATE("(${Variables:",E3,"_kcat","} * ",E3," * ",G3,")","/(${Variables:",E3,"_km","} + (",E3," * ",G3,"))") -> (${Variables:E1_1_1_1_kcat} * E1_1_1_1 * C00469*C00003)/(${Variables:E1_1_1_1_km} + (E1_1_1_1 * C00469*C00003)) | K3: =CONCATENATE("r",D3,": ",F3," -> ",H3," | ",J3) -> r2: C00469+C00003 -> C00084+C00004+C00080 | (${Variables:E1_1_1_1_kcat} * E1_1_1_1 * C00469*C00003)/(${Variables:E1_1_1_1_km} + (E1_1_1_1 * C00469*C00003))
A4: CCB95454.1 | B4: SALIVA_1140 | C4: 1_1_1_1 | D4: 3 | E4: =CONCATENATE("E",Reactions!C4) -> E1_1_1_1 | F4: C00473+C00003 | G4: C00473*C00003 | H4: C00376+C00004+C00080 | I4: C00376*C00004*C00080 | J4: =CONCATENATE("(${Variables:",E4,"_kcat","} * ",E4," * ",G4,")","/(${Variables:",E4,"_km","} + (",E4," * ",G4,"))") -> (${Variables:E1_1_1_1_kcat} * E1_1_1_1 * C00473*C00003)/(${Variables:E1_1_1_1_km} + (E1_1_1_1 * C00473*C00003)) | K4: =CONCATENATE("r",D4,": ",F4," -> ",H4," | ",J4) -> r3: C00473+C00003 -> C00376+C00004+C00080 | (${Variables:E1_1_1_1_kcat} * E1_1_1_1 * C00473*C00003)/(${Variables:E1_1_1_1_km} + (E1_1_1_1 * C00473*C00003))
A5: CCB95454.1 | B5: SALIVA_1140 | C5: 1_1_1_1 | D5: 4 | E5: =CONCATENATE("E",Reactions!C5) -> E1_1_1_1 | F5: C00756+C00003 | G5: C00756*C00003 | H5: C01545+C00004+C00080 | I5: C01545*C00004*C00080 | J5: =CONCATENATE("(${Variables:",E5,"_kcat","} * ",E5," * ",G5,")","/(${Variables:",E5,"_km","} + (",E5," * ",G5,"))") -> (${Variables:E1_1_1_1_kcat} * E1_1_1_1 * C00756*C00003)/(${Variables:E1_1_1_1_km} + (E1_1_1_1 * C00756*C00003)) | K5: =CONCATENATE("r",D5,": ",F5," -> ",H5," | ",J5) -> r4: C00756+C00003 -> C01545+C00004+C00080 | (${Variables:E1_1_1_1_kcat} * E1_1_1_1 * C00756*C00003)/(${Variables:E1_1_1_1_km} + (E1_1_1_1 * C00756*C00003))
A6: CCB95454.1 | B6: SALIVA_1140 | C6: 1_1_1_1 | D6: 5 | E6: =CONCATENATE("E",Reactions!C6) -> E1_1_1_1 | F6: C05444+C00003 | G6: C05444*C00003 | H6: C05445+C00004+C00080 | I6: C05445*C00004*C00080 | J6: =CONCATENATE("(${Variables:",E6,"_kcat","} * ",E6," * ",G6,")","/(${Variables:",E6,"_km","} + (",E6," * ",G6,"))") -> (${Variables:E1_1_1_1_kcat} * E1_1_1_1 * C05444*C00003)/(${Variables:E1_1_1_1_km} + (E1_1_1_1 * C05444*C00003)) | K6: =CONCATENATE("r",D6,": ",F6," -> ",H6," | ",J6) -> r5: C05444+C00003 -> C05445+C00004+C00080 | (${Variables:E1_1_1_1_kcat} * E1_1_1_1 * C05444*C00003)/(${Variables:E1_1_1_1_km} + (E1_1_1_1 * C05444*C00003))
A7: CCB95454.1 | B7: SALIVA_1140 | C7: 1_1_1_1 | D7: 6 | E7: =CONCATENATE("E",Reactions!C7) -> E1_1_1_1 | F7: C05576+C00003 | G7: C05576*C00003 | H7: C05577+C00004+C00080 | I7: C05577*C00004*C00080 | J7: =CONCATENATE("(${Variables:",E7,"_kcat","} * ",E7," * ",G7,")","/(${Variables:",E7,"_km","} + (",E7," * ",G7,"))") -> (${Variables:E1_1_1_1_kcat} * E1_1_1_1 * C05576*C00003)/(${Variables:E1_1_1_1_km} + (E1_1_1_1 * C05576*C00003)) | K7: =CONCATENATE("r",D7,": ",F7," -> ",H7," | ",J7) -> r6: C05576+C00003 -> C05577+C00004+C00080 | (${Variables:E1_1_1_1_kcat} * E1_1_1_1 * C05576*C00003)/(${Variables:E1_1_1_1_km} + (E1_1_1_1 * C05576*C00003))
A8: CCB95454.1 | B8: SALIVA_1140 | C8: 1_1_1_1 | D8: 7 | E8: =CONCATENATE("E",Reactions!C8) -> E1_1_1_1 | F8: C06611+C00003 | G8: C06611*C00003 | H8: C06613+C00004+C00080 | I8: C06613*C00004*C00080 | J8: =CONCATENATE("(${Variables:",E8,"_kcat","} * ",E8," * ",G8,")","/(${Variables:",E8,"_km","} + (",E8," * ",G8,"))") -> (${Variables:E1_1_1_1_kcat} * E1_1_1_1 * C06611*C00003)/(${Variables:E1_1_1_1_km} + (E1_1_1_1 * C06611*C00003)) | K8: =CONCATENATE("r",D8,": ",F8," -> ",H8," | ",J8) -> r7: C06611+C00003 -> C06613+C00004+C00080 | (${Variables:E1_1_1_1_kcat} * E1_1_1_1 * C06611*C00003)/(${Variables:E1_1_1_1_km} + (E1_1_1_1 * C06611*C00003))
A9: CCB95454.1 | B9: SALIVA_1140 | C9: 1_1_1_1 | D9: 8 | E9: =CONCATENATE("E",Reactions!C9) -> E1_1_1_1 | F9: C06612+C00003 | G9: C06612*C00003 | H9: C16348+C00004+C00080 | I9: C16348*C00004*C00080 | J9: =CONCATENATE("(${Variables:",E9,"_kcat","} * ",E9," * ",G9,")","/(${Variables:",E9,"_km","} + (",E9," * ",G9,"))") -> (${Variables:E1_1_1_1_kcat} * E1_1_1_1 * C06612*C00003 )/(${Variables:E1_1_1_1_km} + (E1_1_1_1 * C06612*C00003 )) | K9: =CONCATENATE("r",D9,": ",F9," -> ",H9," | ",J9) -> r8: C06612+C00003 -> C16348+C00004+C00080 | (${Variables:E1_1_1_1_kcat} * E1_1_1_1 * C06612*C00003 )/(${Variables:E1_1_1_1_km} + (E1_1_1_1 * C06612*C00003 ))
A10: CCB95454.1 | B10: SALIVA_1140 | C10: 1_1_1_1 | D10: 9 | E10: =CONCATENATE("E",Reactions!C10) -> E1_1_1_1 | F10: C14089+C00003 | G10: C14089*C00003 | H10: C14090+C00004+C00080 | I10: C14090*C00004*C00080 | J10: =CONCATENATE("(${Variables:",E10,"_kcat","} * ",E10," * ",G10,")","/(${Variables:",E10,"_km","} + (",E10," * ",G10,"))") -> (${Variables:E1_1_1_1_kcat} * E1_1_1_1 * C14089*C00003)/(${Variables:E1_1_1_1_km} + (E1_1_1_1 * C14089*C00003)) | K10: =CONCATENATE("r",D10,": ",F10," -> ",H10," | ",J10) -> r9: C14089+C00003 -> C14090+C00004+C00080 | (${Variables:E1_1_1_1_kcat} * E1_1_1_1 * C14089*C00003)/(${Variables:E1_1_1_1_km} + (E1_1_1_1 * C14089*C00003))
A11: CCB95454.1 | B11: SALIVA_1140 | C11: 1_1_1_1 | D11: 10 | E11: =CONCATENATE("E",Reactions!C11) -> E1_1_1_1 | F11: C02909+C00003 | G11: C02909*C00003 | H11: C14099+C00004+C00080 | I11: C14099*C00004*C00080 | J11: =CONCATENATE("(${Variables:",E11,"_kcat","} * ",E11," * ",G11,")","/(${Variables:",E11,"_km","} + (",E11," * ",G11,"))") -> (${Variables:E1_1_1_1_kcat} * E1_1_1_1 * C02909*C00003)/(${Variables:E1_1_1_1_km} + (E1_1_1_1 * C02909*C00003)) | K11: =CONCATENATE("r",D11,": ",F11," -> ",H11," | ",J11) -> r10: C02909+C00003 -> C14099+C00004+C00080 | (${Variables:E1_1_1_1_kcat} * E1_1_1_1 * C02909*C00003)/(${Variables:E1_1_1_1_km} + (E1_1_1_1 * C02909*C00003))
A12: CCB95454.1 | B12: SALIVA_1140 | C12: 1_1_1_1 | D12: 11 | E12: =CONCATENATE("E",Reactions!C12) -> E1_1_1_1 | F12: C16586+C00003 | G12: C16586*C00003 | H12: C16587+C00004+C00080 | I12: C16587*C00004*C00080 | J12: =CONCATENATE("(${Variables:",E12,"_kcat","} * ",E12," * ",G12,")","/(${Variables:",E12,"_km","} + (",E12," * ",G12,"))") -> (${Variables:E1_1_1_1_kcat} * E1_1_1_1 * C16586*C00003)/(${Variables:E1_1_1_1_km} + (E1_1_1_1 * C16586*C00003)) | K12: =CONCATENATE("r",D12,": ",F12," -> ",H12," | ",J12) -> r11: C16586+C00003 -> C16587+C00004+C00080 | (${Variables:E1_1_1_1_kcat} * E1_1_1_1 * C16586*C00003)/(${Variables:E1_1_1_1_km} + (E1_1_1_1 * C16586*C00003))
A13: CCB95454.1 | B13: SALIVA_1140 | C13: 1_1_1_1 | D13: 12 | E13: =CONCATENATE("E",Reactions!C13) -> E1_1_1_1 | F13: C00114+C00003 | G13: C00114*C00003 | H13: C00576+C00004+C00080 | I13: C00576*C00004*C00080 | J13: =CONCATENATE("(${Variables:",E13,"_kcat","} * ",E13," * ",G13,")","/(${Variables:",E13,"_km","} + (",E13," * ",G13,"))") -> (${Variables:E1_1_1_1_kcat} * E1_1_1_1 * C00114*C00003 )/(${Variables:E1_1_1_1_km} + (E1_1_1_1 * C00114*C00003 )) | K13: =CONCATENATE("r",D13,": ",F13," -> ",H13," | ",J13) -> r12: C00114+C00003 -> C00576+C00004+C00080 | (${Variables:E1_1_1_1_kcat} * E1_1_1_1 * C00114*C00003 )/(${Variables:E1_1_1_1_km} + (E1_1_1_1 * C00114*C00003 ))
... A779: CCB94712.1 | B779: SALIVA_0369 | C779: 6_4_1_2 | D779: 778 | E779: =CONCATENATE("E",Reactions!C779) -> E6_4_1_2 | F779: C00002+C00024+C00288 | G779: C00002*C00024*C00288 | H779: C00008+C00009+C00083 | I779: C00008*C00009*C00083 | J779: =CONCATENATE("(${Variables:",E779,"_kcat","} * ",E779," * ",G779,")","/(${Variables:",E779,"_km","} + (",E779," * ",G779,"))") -> (${Variables:E6_4_1_2_kcat} * E6_4_1_2 * C00002*C00024*C00288 )/(${Variables:E6_4_1_2_km} + (E6_4_1_2 * C00002*C00024*C00288 )) | K779: =CONCATENATE("r",D779,": ",F779," -> ",H779," | ",J779) -> r778: C00002+C00024+C00288 -> C00008+C00009+C00083 | (${Variables:E6_4_1_2_kcat} * E6_4_1_2 * C00002*C00024*C00288 )/(${Variables:E6_4_1_2_km} + (E6_4_1_2 * C00002*C00024*C00288 ))
